<?xml version="1.0" encoding="utf-8"?>
<!-- =================================================================================== -->
<!-- |    This document was autogenerated by xacro from lm3.xacro                      | -->
<!-- |    EDITING THIS FILE BY HAND IS NOT RECOMMENDED                                 | -->
<!-- =================================================================================== -->
<robot name="lebai_lm3">
  <link name="world"/>
  <!-- link list -->
  <link name="base_link">
    <visual>
      <geometry>
        <mesh filename="package://lebai_lm3_support/meshes/lm3/visual/base_link.stl"/>
      </geometry>
      <material name="white">
        <color rgba="0.86 0.85 0.81 1.0"/>
      </material>
    </visual>
    <collision>
      <geometry>
        <mesh filename="package://lebai_lm3_support/meshes/lm3/collision/base_link.stl"/>
      </geometry>
      <material name="yellow">
        <color rgba="0.96 0.76 0.13 1.0"/>
      </material>
    </collision>
  </link>
  <link name="link_1">
    <visual>
      <geometry>
        <mesh filename="package://lebai_lm3_support/meshes/lm3/visual/link1.stl"/>
      </geometry>
      <material name="white">
        <color rgba="0.86 0.85 0.81 1.0"/>
      </material>
    </visual>
    <collision>
      <geometry>
        <mesh filename="package://lebai_lm3_support/meshes/lm3/collision/link1.stl"/>
      </geometry>
      <material name="yellow">
        <color rgba="0.96 0.76 0.13 1.0"/>
      </material>
    </collision>
    <inertial>
      <origin rpy="0.0 0.0 0.0" xyz="0.0 -0.011 -0.015"/>
      <mass value="2.147"/>
      <inertia ixx="0.0082391363" ixy="0" ixz="0" iyy="0.0076087775" iyz="0.00032383729" izz="0.0032573589"/>
    </inertial>
  </link>
  <link name="link_2">
    <visual>
      <geometry>
        <mesh filename="package://lebai_lm3_support/meshes/lm3/visual/link2.stl"/>
      </geometry>
      <material name="white">
        <color rgba="0.86 0.85 0.81 1.0"/>
      </material>
    </visual>
    <collision>
      <geometry>
        <mesh filename="package://lebai_lm3_support/meshes/lm3/collision/link2.stl"/>
      </geometry>
      <material name="yellow">
        <color rgba="0.96 0.76 0.13 1.0"/>
      </material>
    </collision>
    <inertial>
      <origin rpy="0.0 0.0 0.0" xyz="-0.134 0.0 0.094"/>
      <mass value="1.972"/>
      <inertia ixx="0.0017128976" ixy="0.0" ixz="0.000073751933" iyy="0.033612233" iyz="0.0" izz="0.03384798"/>
    </inertial>
  </link>
  <link name="link_3">
    <visual>
      <geometry>
        <mesh filename="package://lebai_lm3_support/meshes/lm3/visual/link3.stl"/>
      </geometry>
      <material name="white">
        <color rgba="0.86 0.85 0.81 1.0"/>
      </material>
    </visual>
    <collision>
      <geometry>
        <mesh filename="package://lebai_lm3_support/meshes/lm3/collision/link3.stl"/>
      </geometry>
      <material name="yellow">
        <color rgba="0.96 0.76 0.13 1.0"/>
      </material>
    </collision>
    <inertial>
      <origin rpy="0.0 0.0 0.0" xyz="-0.102 0.0 0.019"/>
      <mass value="1.668"/>
      <inertia ixx="0.0017092842" ixy="0.0" ixz="-0.002750573" iyy="0.022563964" iyz="0.0" izz="0.022383877"/>
    </inertial>
  </link>
  <link name="link_4">
    <visual>
      <geometry>
        <mesh filename="package://lebai_lm3_support/meshes/lm3/visual/link4.stl"/>
      </geometry>
      <material name="white">
        <color rgba="0.86 0.85 0.81 1.0"/>
      </material>
    </visual>
    <collision>
      <geometry>
        <mesh filename="package://lebai_lm3_support/meshes/lm3/collision/link4.stl"/>
      </geometry>
      <material name="yellow">
        <color rgba="0.96 0.76 0.13 1.0"/>
      </material>
    </collision>
    <inertial>
      <origin rpy="0.0 0.0 0.0" xyz="0.0 0.011 -0.039"/>
      <mass value="0.969"/>
      <inertia ixx="0.0018744072" ixy="0.0" ixz="0.0" iyy="0.0017809517" iyz="-0.00040039676" izz="0.00079617326"/>
    </inertial>
  </link>
  <link name="link_5">
    <visual>
      <geometry>
        <mesh filename="package://lebai_lm3_support/meshes/lm3/visual/link5.stl"/>
      </geometry>
      <material name="white">
        <color rgba="0.86 0.85 0.81 1.0"/>
      </material>
    </visual>
    <collision>
      <geometry>
        <mesh filename="package://lebai_lm3_support/meshes/lm3/collision/link5.stl"/>
      </geometry>
      <material name="yellow">
        <color rgba="0.96 0.76 0.13 1.0"/>
      </material>
    </collision>
    <inertial>
      <origin rpy="0.0 0.0 0.0" xyz="0.0 -0.011 -0.039"/>
      <mass value="0.969"/>
      <inertia ixx="0.0018744072" ixy="0.0" ixz="0.0" iyy="0.0017809517" iyz="0.00040039676" izz="0.00079617326"/>
    </inertial>
  </link>
  <link name="link_6">
    <visual>
      <geometry>
        <mesh filename="package://lebai_lm3_support/meshes/lm3/visual/link6.stl"/>
      </geometry>
      <material name="white">
        <color rgba="0.86 0.85 0.81 1.0"/>
      </material>
    </visual>
    <collision>
      <geometry>
        <mesh filename="package://lebai_lm3_support/meshes/lm3/collision/link6.stl"/>
      </geometry>
      <material name="yellow">
        <color rgba="0.96 0.76 0.13 1.0"/>
      </material>
    </collision>
    <inertial>
      <origin rpy="0 0 0" xyz="0 0 -0.049"/>
      <mass value="0.584"/>
      <inertia ixx="0.00050434988" ixy="0.0" ixz="0.0" iyy="0.0005155908" iyz="0.0" izz="0.0004119313"/>
    </inertial>
  </link>
  <link name="base"/>
  <link name="tool0"/>
  <!-- end of link list -->
  <!-- joint list -->
  <joint name="joint_1" type="revolute">
    <parent link="base_link"/>
    <child link="link_1"/>
    <origin rpy="0.0 0.0 0.0" xyz="0.0 0.0 0.21583"/>
    <axis xyz="0 0 1"/>
    <limit effort="100" lower="-4" upper="4" velocity="1"/>
  </joint>
  <joint name="joint_2" type="revolute">
    <parent link="link_1"/>
    <child link="link_2"/>
    <origin rpy="1.570796327 0 0" xyz="0.0 0.0 0.0"/>
    <axis xyz="0 0 1"/>
    <limit effort="100" lower="-4" upper="4" velocity="1"/>
  </joint>
  <joint name="joint_3" type="revolute">
    <parent link="link_2"/>
    <child link="link_3"/>
    <origin rpy="0 0 0" xyz="-0.28 0 0"/>
    <axis xyz="0 0 1"/>
    <limit effort="100" lower="-4" upper="4" velocity="1"/>
  </joint>
  <joint name="joint_4" type="revolute">
    <parent link="link_3"/>
    <child link="link_4"/>
    <origin rpy="0 0 0" xyz="-0.26 0.0 0.12063"/>
    <axis xyz="0 0 1"/>
    <limit effort="100" lower="-4" upper="4" velocity="1"/>
  </joint>
  <joint name="joint_5" type="revolute">
    <parent link="link_4"/>
    <child link="link_5"/>
    <origin rpy="1.570796327 0 0" xyz="0 -0.09833 0"/>
    <axis xyz="0 0 1"/>
    <limit effort="5.5" lower="-4" upper="4" velocity="1"/>
  </joint>
  <joint name="joint_6" type="revolute">
    <parent link="link_5"/>
    <child link="link_6"/>
    <origin rpy="-1.570796327 0 0" xyz="0  0.08343 0"/>
    <axis xyz="0 0 1"/>
    <limit effort="4.6" lower="-4" upper="4" velocity="1"/>
  </joint>
  <joint name="joint_6-tool0" type="fixed">
    <parent link="link_6"/>
    <child link="tool0"/>
    <origin rpy="0 0 0" xyz="0 0 0"/>
  </joint>
  <joint name="base_link-base" type="fixed">
    <parent link="base_link"/>
    <child link="base"/>
    <origin rpy="0.0 0.0 0.0" xyz="0.0 0.0 0.0"/>
  </joint>
  <!-- end of joint list -->
  <joint name="fixed" type="fixed">
    <parent link="world"/>
    <child link="base_link"/>
  </joint>
</robot>

